<?xml version='1.0'?>
<robot name="kammo" xmlns:sensor="http://playerstage.sourceforge.net/gazebo/xmlschema/#sensor"
       xmlns:controller="http://playerstage.sourceforge.net/gazebo/xmlschema/#controller"
       xmlns:interface="http://playerstage.sourceforge.net/gazebo/xmlschema/#interface"
       xmlns:xacro="http://playerstage.sourceforge.net/gazebo/xmlschema/#xacro">

<gazebo>
  <plugin name="skid_steer_drive_controller" filename="libgazebo_ros_skid_steer_drive.so">
    <updateRate>100.0</updateRate>
    <robotNamespace>/</robotNamespace>
    <leftFrontJoint>front_left_wheel_joint</leftFrontJoint>
    <rightFrontJoint>front_right_wheel_joint</rightFrontJoint>
    <leftRearJoint>left_wheel_joint</leftRearJoint>
    <rightRearJoint>right_wheel_joint</rightRearJoint>
    <wheelSeparation>0.515</wheelSeparation>
    <wheelDiameter>0.07</wheelDiameter>
    <robotBaseFrame>base_link</robotBaseFrame>
    <torque>20</torque>
    <topicName>cmd_vel</topicName>
    <broadcastTF>false</broadcastTF>
  </plugin>
</gazebo>


  <xacro:property name="camera_link" value="0.05" /> <!-- Size of square 'camera' box -->


 <joint name="camera_joint" type="fixed">
    <axis xyz="0 1 0" />
    <origin xyz="0.3 0.15 0.3" rpy="0 0 0"/>
    <parent link="base_link"/>
    <child link="camera_link"/>
  </joint>

  <!-- Camera -->
  <link name="camera_link">
    <collision>
      <origin xyz="0 0 0" rpy="0 0 0"/>
      <geometry>
    <box size="${camera_link} ${camera_link} ${camera_link}"/>
      </geometry>
    </collision>

    <visual>
      <origin xyz="0 0 0" rpy="0 0 0"/>
      <geometry>
    <box size="${camera_link} ${camera_link} ${camera_link}"/>
      </geometry>
      <material name="red"/>
    </visual>

    <inertial>
      <mass value="1e-5" />
      <origin xyz="0 0 0" rpy="0 0 0"/>
      <inertia ixx="1e-6" ixy="0" ixz="0" iyy="1e-6" iyz="0" izz="1e-6" />
    </inertial>
  </link>





<gazebo reference="front_caster">
    <sensor name="front_caster_camera" type="depth">
    <update_rate>20</update_rate>
    <camera>
      <horizontal_fov>1.047198</horizontal_fov>
      <image>
        <width>640</width>
        <height>480</height>
        <format>R8G8B8</format>
      </image>
      <clip>
        <near>0.05</near>
        <far>3</far>
      </clip>
    </camera>
    <plugin name="front_caster_controller" filename="libgazebo_ros_openni_kinect.so">
      <baseline>0.2</baseline>
      <alwaysOn>true</alwaysOn>
      <updateRate>1.0</updateRate>
      <cameraName>a_ir</cameraName>
      <imageTopicName>/a/color/image_raw</imageTopicName>
      <cameraInfoTopicName>/a/color/camera_info</cameraInfoTopicName>
      <depthImageTopicName>/a/depth/image_raw</depthImageTopicName>
      <depthImageInfoTopicName>/a/depth/camera_info</depthImageInfoTopicName>
      <pointCloudTopicName>/a/depth/points</pointCloudTopicName>
      <frameName>5</frameName>
      <pointCloudCutoff>0.5</pointCloudCutoff>
      <pointCloudCutoffMax>3.0</pointCloudCutoffMax>
      <distortionK1>0.00000001</distortionK1>
      <distortionK2>0.00000001</distortionK2>
      <distortionK3>0.00000001</distortionK3>
      <distortionT1>0.00000001</distortionT1>
      <distortionT2>0.00000001</distortionT2>
      <CxPrime>0</CxPrime>
      <Cx>0</Cx>
      <Cy>0</Cy>
      <focalLength>0</focalLength>
      <hackBaseline>0</hackBaseline>
    </plugin>
  </sensor>
  </gazebo>




    <link name="base_link">
     <collision>
        <geometry>
                <box size="0.6 0.3 0.3"/>
            </geometry>
            <material name="silver">
                <color rgba="0.75 0.75 0.75 1"/>
            </material>
    </collision>
    <inertial>
            <mass value="1.0"/>
            <inertia ixx="0.015" iyy="0.0375" izz="0.0375" ixy="0" ixz="0" iyz="0"/>
        </inertial>    
        <visual>
            <geometry>
                <box size="0.6 0.3 0.3"/>
            </geometry>
            <material name="silver">
                <color rgba="0.75 0.75 0.75 1"/>
            </material>
        </visual>

    </link>

    <link name="front_caster">
       <collision>
            <geometry>
                    <box size="0.1 0.1 0.3"/>
            </geometry>
            <material name="silver"/>
        </collision>
        <inertial>
                <mass value="0.1"/>
                <inertia ixx="0.00083" iyy="0.00083" izz="0.000167" ixy="0" ixz="0" iyz="0"/>
        </inertial>
        <visual>
            <geometry>
                    <box size="0.1 0.1 0.3"/>
            </geometry>
            <material name="silver"/>
        </visual>       
    </link>


    <joint name="front_caster_joint" type="continuous">
        <axis xyz="0 0 1"/>
        <parent link="base_link"/>
        <child link="front_caster"/>
        <origin rpy="0 0 0" xyz="0 0.15 0"/>
    </joint>


    <link name="front_right_wheel">
        <collision>
             <geometry>
                <cylinder length="0.05" radius="0.035"/>
            </geometry>
            <material name="black">
                <color rgba="0 0 0 1"/>
            </material>
        </collision>
         <inertial> 
            <mass value="0.1"/>
            <inertia ixx="5.1458e-5" iyy="5.1458e-5" izz="6.125e-5" ixy="0" ixz="0" iyz="0"/>
        </inertial>
        <visual>
            <geometry>
                <cylinder length="0.05" radius="0.035"/>
            </geometry>
            <material name="black">
                <color rgba="0 0 0 1"/>
            </material>
        </visual>
    </link>


    <joint name="front_right_wheel_joint" type="continuous">
        <axis xyz="0 0 1"/>
        <parent link="base_link"/>
        <child link="front_right_wheel"/>
        <origin rpy="-1.5708 0 0" xyz="0.2825 -0.125 -.15"/>
    </joint>


    <link name="right_wheel">
        <collision>
             <geometry>
                <cylinder length="0.05" radius="0.035"/>
            </geometry>
            <material name="black">
                <color rgba="0 0 0 1"/>
            </material>
        </collision>
         <inertial> 
            <mass value="0.1"/>
            <inertia ixx="5.1458e-5" iyy="5.1458e-5" izz="6.125e-5" ixy="0" ixz="0" iyz="0"/>
        </inertial>
        <visual>
            <geometry>
                <cylinder length="0.05" radius="0.035"/>
            </geometry>
            <material name="black">
                <color rgba="0 0 0 1"/>
            </material>
        </visual>
    </link>


    <joint name="right_wheel_joint" type="continuous">
        <axis xyz="0 0 1"/>
        <parent link="base_link"/>
        <child link="right_wheel"/>
        <origin rpy="-1.5708 0 0" xyz="-0.2825 -0.125 -.15"/>
    </joint>


    <link name="left_wheel">
        <collision>
            <geometry>
                <cylinder length="0.05" radius="0.035"/>
            </geometry>
        </collision>
        <inertial>
            <mass value="0.1"/>
            <inertia ixx="5.1458e-5" iyy="5.1458e-5" izz="6.125e-5" ixy="0" ixz="0" iyz="0"/>
        </inertial>
        <visual>
            <geometry>
                <cylinder length="0.05" radius="0.035"/>
            </geometry>
            <material name="black"/>
        </visual>
    </link>
  <joint name="left_wheel_joint" type="continuous">
        <axis xyz="0 0 1"/>
        <parent link="base_link"/>
        <child link="left_wheel"/>
        <origin rpy="-1.5708 0 0" xyz="-0.2825 0.125 -.15"/>
    </joint>

<link name="front_left_wheel">
        <collision>
            <geometry>
                <cylinder length="0.05" radius="0.035"/>
            </geometry>
        </collision>
        <inertial>
            <mass value="0.1"/>
            <inertia ixx="5.1458e-5" iyy="5.1458e-5" izz="6.125e-5" ixy="0" ixz="0" iyz="0"/>
        </inertial>
        <visual>
            <geometry>
                <cylinder length="0.05" radius="0.035"/>
            </geometry>
            <material name="black"/>
        </visual>
    </link>
  <joint name="front_left_wheel_joint" type="continuous">
        <axis xyz="0 0 1"/>
        <parent link="base_link"/>
        <child link="front_left_wheel"/>
        <origin rpy="-1.5708 0 0" xyz="0.2825 0.125 -.15"/>
    </joint>

</robot>
